Workbook
Name Slicer_AGE: #N/A
Name Slicer_COUNTRY_NAME: #N/A
Name Slicer_GENDER: #N/A
Name Slicer_SPORTS: #N/A

Sheet Sports_details
A1: SPORTS TYPE | B1: SPORTS
A2: INDOOR | B2: Cycling Track
A3: INDOOR | B3: Boxing
A4: OUTDOOR | B4: Football
A5: OUTDOOR | B5: Alpine Skiing
A6: INDOOR | B6: Water Polo
A7: INDOOR | B7: Fencing
A8: OUTDOOR | B8: Cycling Road
A9: INDOOR | B9: Curling
A10: INDOOR | B10: Shooting
A11: OUTDOOR | B11: Freestyle Skiing
A12: OUTDOOR | B12: Archery
... A33: INDOOR | B33: Swimming

Sheet Location_details
A1: LANGUAGE | B1: English | C1: Portuguese | D1: English | E1: German | F1: English | G1: German | H1: French | I1: Spanish | J1: Spanish | K1: Dutch | L1: Swedish | M1: Portuguese
A2: COUNTRYCODE | B2: US | C2: BR | D2: GB | E2: DE | F2: OZ | G2: AU | H2: FR | I2: AG | J2: ES | K2: DU | L2: SV | M2: PR
A3: COUNTRY NAME | B3: USA | C3: BRAZIL | D3: UK | E3: GERMANY | F3: AUSTRALIA | G3: AUSTRIA | H3: FRANCE | I3: ARGENTINA | J3: SPAIN | K3: NETHERLANDS | L3: SWEDEN | M3: BRAZIL

Sheet Sportsmen
A1: MEMBER ID | B1: FULL NAME | C1: PREFIX | D1: FIRSTNAME | E1: MIDDLENAME | F1: LASTNAME | G1: BIRTHDATE | H1: BIRTH DATE | I1: AGE | J1: ZODIAC | K1: GENDER | L1: COUNTRYCODE | M1: COUNTRY NAME | N1: LANGUAGE | O1: EMAIL | P1: BLOODTYPE | Q1: SPORT LOCATION | R1: SPORTS | S1: SALARY | T1: wt.
A2: =1 -> 1 | B2: =_xlfn.CONCAT(C2," ",D2," ",E2," ",F2) -> Ms. Annie Abbott | C2: Ms. | D2: Annie | F2: Abbott | G2: 1997 | H2: =DATE(G2,1,1) -> 35431 | I2: =2026-G2 -> 29 | J2: Libra | K2: Female | L2: US | M2: =_xlfn.XLOOKUP(Sportsmen!L2,Location_details!A2:M2,Location_details!A3:M3) -> USA | N2: =_xlfn.XLOOKUP(L2,Location_details!$A$2:$M$2,Location_details!$A$1:$M$1) -> English | O2: =LOWER(F2&"."&D2&"@xyz.org") -> abbott.annie@xyz.org | P2: A− | Q2: =_xlfn.XLOOKUP(R2,Sports_details!B:B,Sports_details!A:A) -> INDOOR | R2: Cycling Track | S2: 80.73 | T2: 94
A3: 2 | B3: =_xlfn.CONCAT(C3," ",D3," ",E3," ",F3) -> Ms. Aurelie Liesuchke | C3: Ms. | D3: Aurelie | F3: Liesuchke | G3: 1992 | H3: =DATE(G3,1,1) -> 33604 | I3: =2026-G3 -> 34 | J3: Aquarius | K3: Female | L3: US | M3: =_xlfn.XLOOKUP(L3,Location_details!$A$2:$M$2,Location_details!$A$3:$M$3) -> USA | N3: =_xlfn.XLOOKUP(L3,Location_details!$A$2:$M$2,Location_details!$A$1:$M$1) -> English | O3: =LOWER(F3&"."&D3&"@xyz.org") -> liesuchke.aurelie@xyz.org | P3: O− | Q3: =_xlfn.XLOOKUP(R3,Sports_details!B:B,Sports_details!A:A) -> INDOOR | R3: Boxing | S3: 87.47 | T3: 84
A4: 3 | B4: =_xlfn.CONCAT(C4," ",D4," ",E4," ",F4) -> Sr. Tomas Ferreira Filho | C4: Sr. | D4: Tomas | E4: Ferreira | F4: Filho | G4: 1969 | H4: =DATE(G4,1,1) -> 25204 | I4: =2026-G4 -> 57 | J4: Cancer | K4: Male | L4: BR | M4: =_xlfn.XLOOKUP(L4,Location_details!$A$2:$M$2,Location_details!$A$3:$M$3) -> BRAZIL | N4: =_xlfn.XLOOKUP(L4,Location_details!$A$2:$M$2,Location_details!$A$1:$M$1) -> Portuguese | O4: =LOWER(F4&"."&D4&"xyz.com") -> filho.tomasxyz.com | P4: A− | Q4: =_xlfn.XLOOKUP(R4,Sports_details!B:B,Sports_details!A:A) -> OUTDOOR | R4: Football | S4: 64.72 | T4: 53
A5: 4 | B5: =_xlfn.CONCAT(C5," ",D5," ",E5," ",F5) -> Ms. Darby Cruickshank | C5: Ms. | D5: Darby | F5: Cruickshank | G5: 1975 | H5: =DATE(G5,1,1) -> 27395 | I5: =2026-G5 -> 51 | J5: Taurus | K5: Female | L5: US | M5: =_xlfn.XLOOKUP(L5,Location_details!$A$2:$M$2,Location_details!$A$3:$M$3) -> USA | N5: =_xlfn.XLOOKUP(L5,Location_details!$A$2:$M$2,Location_details!$A$1:$M$1) -> English | O5: =LOWER(F5&"."&D5&"@xyz.org") -> cruickshank.darby@xyz.org | P5: O− | Q5: =_xlfn.XLOOKUP(R5,Sports_details!B:B,Sports_details!A:A) -> OUTDOOR | R5: Alpine Skiing | S5: 110.8 | T5: 49
A6: 5 | B6: =_xlfn.CONCAT(C6," ",D6," ",E6," ",F6) -> Dr. Jaydon Borer | C6: Dr. | D6: Jaydon | F6: Borer | G6: 1970 | H6: =DATE(G6,1,1) -> 25569 | I6: =2026-G6 -> 56 | J6: Taurus | K6: Male | L6: US | M6: =_xlfn.XLOOKUP(L6,Location_details!$A$2:$M$2,Location_details!$A$3:$M$3) -> USA | N6: =_xlfn.XLOOKUP(L6,Location_details!$A$2:$M$2,Location_details!$A$1:$M$1) -> English | O6: =LOWER(F6&"."&D6&"@xyz.org") -> borer.jaydon@xyz.org | P6: B− | Q6: =_xlfn.XLOOKUP(R6,Sports_details!B:B,Sports_details!A:A) -> INDOOR | R6: Water Polo | S6: 56.92 | T6: 85
A7: 6 | B7: =_xlfn.CONCAT(C7," ",D7," ",E7," ",F7) -> Mr. Moriah Lynch | C7: Mr. | D7: Moriah | F7: Lynch | G7: 1992 | H7: =DATE(G7,1,1) -> 33604 | I7: =2026-G7 -> 34 | J7: Sagittarius | K7: Male | L7: US | M7: =_xlfn.XLOOKUP(L7,Location_details!$A$2:$M$2,Location_details!$A$3:$M$3) -> USA | N7: =_xlfn.XLOOKUP(L7,Location_details!$A$2:$M$2,Location_details!$A$1:$M$1) -> English | O7: =LOWER(F7&"."&D7&"@xyz.org") -> lynch.moriah@xyz.org | P7: O− | Q7: =_xlfn.XLOOKUP(R7,Sports_details!B:B,Sports_details!A:A) -> INDOOR | R7: Fencing | S7: 51.13 | T7: 83
A8: 7 | B8: =_xlfn.CONCAT(C8," ",D8," ",E8," ",F8) -> Ms. Amiya Eichmann | C8: Ms. | D8: Amiya | F8: Eichmann | G8: 1999 | H8: =DATE(G8,1,1) -> 36161 | I8: =2026-G8 -> 27 | J8: Leo | K8: Female | L8: US | M8: =_xlfn.XLOOKUP(L8,Location_details!$A$2:$M$2,Location_details!$A$3:$M$3) -> USA | N8: =_xlfn.XLOOKUP(L8,Location_details!$A$2:$M$2,Location_details!$A$1:$M$1) -> English | O8: =LOWER(F8&"."&D8&"@xyz.org") -> eichmann.amiya@xyz.org | P8: B− | Q8: =_xlfn.XLOOKUP(R8,Sports_details!B:B,Sports_details!A:A) -> OUTDOOR | R8: Cycling Road | S8: 65.47 | T8: 61
A9: 8 | B9: =_xlfn.CONCAT(C9," ",D9," ",E9," ",F9) -> Mr. Pierce Rau | C9: Mr. | D9: Pierce | F9: Rau | G9: 1963 | H9: =DATE(G9,1,1) -> 23012 | I9: =2026-G9 -> 63 | J9: Taurus | K9: Male | L9: US | M9: =_xlfn.XLOOKUP(L9,Location_details!$A$2:$M$2,Location_details!$A$3:$M$3) -> USA | N9: =_xlfn.XLOOKUP(L9,Location_details!$A$2:$M$2,Location_details!$A$1:$M$1) -> English | O9: =LOWER(F9&"."&D9&"@xyz.org") -> rau.pierce@xyz.org | P9: A+ | Q9: =_xlfn.XLOOKUP(R9,Sports_details!B:B,Sports_details!A:A) -> INDOOR | R9: Curling | S9: 109.9 | T9: 106
A10: 9 | B10: =_xlfn.CONCAT(C10," ",D10," ",E10," ",F10) -> Ms. Amelia Stevens | C10: Ms. | D10: Amelia | F10: Stevens | G10: 1971 | H10: =DATE(G10,1,1) -> 25934 | I10: =2026-G10 -> 55 | J10: Aquarius | K10: Female | L10: GB | M10: =_xlfn.XLOOKUP(L10,Location_details!$A$2:$M$2,Location_details!$A$3:$M$3) -> UK | N10: =_xlfn.XLOOKUP(L10,Location_details!$A$2:$M$2,Location_details!$A$1:$M$1) -> English | O10: =LOWER(F10&"."&D10&"@xyz.org") -> stevens.amelia@xyz.org | P10: A+ | Q10: =_xlfn.XLOOKUP(R10,Sports_details!B:B,Sports_details!A:A) -> INDOOR | R10: Shooting | S10: 60.06 | T10: 65
A11: 10 | B11: =_xlfn.CONCAT(C11," ",D11," ",E11," ",F11) -> Mr. Toby Simpson | C11: Mr. | D11: Toby | F11: Simpson | G11: 1964 | H11: =DATE(G11,1,1) -> 23377 | I11: =2026-G11 -> 62 | J11: Sagittarius | K11: Male | L11: GB | M11: =_xlfn.XLOOKUP(L11,Location_details!$A$2:$M$2,Location_details!$A$3:$M$3) -> UK | N11: =_xlfn.XLOOKUP(L11,Location_details!$A$2:$M$2,Location_details!$A$1:$M$1) -> English | O11: =LOWER(F11&"."&D11&"@xyz.org") -> simpson.toby@xyz.org | P11: O+ | Q11: =_xlfn.XLOOKUP(R11,Sports_details!B:B,Sports_details!A:A) -> OUTDOOR | R11: Cycling Road | S11: 32.76 | T11: 63
A12: 11 | B12: =_xlfn.CONCAT(C12," ",D12," ",E12," ",F12) -> Sir Ethan Murphy | C12: Sir | D12: Ethan | F12: Murphy | G12: 1986 | H12: =DATE(G12,1,1) -> 31413 | I12: =2026-G12 -> 40 | J12: Scorpio | K12: Male | L12: GB | M12: =_xlfn.XLOOKUP(L12,Location_details!$A$2:$M$2,Location_details!$A$3:$M$3) -> UK | N12: =_xlfn.XLOOKUP(L12,Location_details!$A$2:$M$2,Location_details!$A$1:$M$1) -> English | O12: =LOWER(F12&"."&D12&"@xyz.org") -> murphy.ethan@xyz.org | P12: O+ | Q12: =_xlfn.XLOOKUP(R12,Sports_details!B:B,Sports_details!A:A) -> OUTDOOR | R12: Freestyle Skiing | S12: 99.61 | T12: 104
A13: 12 | B13: =_xlfn.CONCAT(C13," ",D13," ",E13," ",F13) -> Mrs. Ashley Wood | C13: Mrs. | D13: Ashley | F13: Wood | G13: 1977 | H13: =DATE(G13,1,1) -> 28126 | I13: =2026-G13 -> 49 | J13: Libra | K13: Female | L13: GB | M13: =_xlfn.XLOOKUP(L13,Location_details!$A$2:$M$2,Location_details!$A$3:$M$3) -> UK | N13: =_xlfn.XLOOKUP(L13,Location_details!$A$2:$M$2,Location_details!$A$1:$M$1) -> English | O13: =LOWER(F13&"."&D13&"@xyz.org") -> wood.ashley@xyz.org | P13: O+ | Q13: =_xlfn.XLOOKUP(R13,Sports_details!B:B,Sports_details!A:A) -> OUTDOOR | R13: Archery | S13: 56.6 | T13: 101
A14: 13 | B14: =_xlfn.CONCAT(C14," ",D14," ",E14," ",F14) -> Ms. Megan Scott | C14: Ms. | D14: Megan | F14: Scott | G14: 1977 | H14: =DATE(G14,1,1) -> 28126 | I14: =2026-G14 -> 49 | J14: Aquarius | K14: Female | L14: GB | M14: =_xlfn.XLOOKUP(L14,Location_details!$A$2:$M$2,Location_details!$A$3:$M$3) -> UK | N14: =_xlfn.XLOOKUP(L14,Location_details!$A$2:$M$2,Location_details!$A$1:$M$1) -> English | O14: =LOWER(F14&"."&D14&"@xyz.org") -> scott.megan@xyz.org | P14: A− | Q14: =_xlfn.XLOOKUP(R14,Sports_details!B:B,Sports_details!A:A) -> OUTDOOR | R14: Rugby | S14: 117.4 | T14: 71
A15: 14 | B15: =_xlfn.CONCAT(C15," ",D15," ",E15," ",F15) -> Hr. Helmut Weinhae | C15: Hr. | D15: Helmut | F15: Weinhae | G15: 1959 | H15: =DATE(G15,1,1) -> 21551 | I15: =2026-G15 -> 67 | J15: Virgo | K15: Male | L15: DE | M15: =_xlfn.XLOOKUP(L15,Location_details!$A$2:$M$2,Location_details!$A$3:$M$3) -> GERMANY | N15: =_xlfn.XLOOKUP(L15,Location_details!$A$2:$M$2,Location_details!$A$1:$M$1) -> German | O15: =LOWER(F15&"."&D15&"xyz.com") -> weinhae.helmutxyz.com | P15: A+ | Q15: =_xlfn.XLOOKUP(R15,Sports_details!B:B,Sports_details!A:A) -> OUTDOOR | R15: Canoe Sprint | S15: 64.86 | T15: 68
A16: 15 | B16: =_xlfn.CONCAT(C16," ",D16," ",E16," ",F16) -> Prof. Milena Schotin | C16: Prof. | D16: Milena | F16: Schotin | G16: 1965 | H16: =DATE(G16,1,1) -> 23743 | I16: =2026-G16 -> 61 | J16: Pisces | K16: Female | L16: DE | M16: =_xlfn.XLOOKUP(L16,Location_details!$A$2:$M$2,Location_details!$A$3:$M$3) -> GERMANY | N16: =_xlfn.XLOOKUP(L16,Location_details!$A$2:$M$2,Location_details!$A$1:$M$1) -> German | O16: =LOWER(F16&"."&D16&"xyz.com") -> schotin.milenaxyz.com | P16: O+ | Q16: =_xlfn.XLOOKUP(R16,Sports_details!B:B,Sports_details!A:A) -> INDOOR | R16: Cycling BMX | S16: 10.24 | T16: 105
A17: 16 | B17: =_xlfn.CONCAT(C17," ",D17," ",E17," ",F17) -> Hr. Lothar Birnbaum | C17: Hr. | D17: Lothar | F17: Birnbaum | G17: 1969 | H17: =DATE(G17,1,1) -> 25204 | I17: =2026-G17 -> 57 | J17: Cancer | K17: Male | L17: DE | M17: =_xlfn.XLOOKUP(L17,Location_details!$A$2:$M$2,Location_details!$A$3:$M$3) -> GERMANY | N17: =_xlfn.XLOOKUP(L17,Location_details!$A$2:$M$2,Location_details!$A$1:$M$1) -> German | O17: =LOWER(F17&"."&D17&"xyz.com") -> birnbaum.lotharxyz.com | P17: O+ | Q17: =_xlfn.XLOOKUP(R17,Sports_details!B:B,Sports_details!A:A) -> OUTDOOR | R17: Alpine Skiing | S17: 88.76 | T17: 49
A18: 17 | B18: =_xlfn.CONCAT(C18," ",D18," ",E18," ",F18) -> Hr. Pietro Stolze | C18: Hr. | D18: Pietro | F18: Stolze | G18: 1972 | H18: =DATE(G18,1,1) -> 26299 | I18: =2026-G18 -> 54 | J18: Libra | K18: Male | L18: DE | M18: =_xlfn.XLOOKUP(L18,Location_details!$A$2:$M$2,Location_details!$A$3:$M$3) -> GERMANY | N18: =_xlfn.XLOOKUP(L18,Location_details!$A$2:$M$2,Location_details!$A$1:$M$1) -> German | O18: =LOWER(F18&"."&D18&"xyz.com") -> stolze.pietroxyz.com | P18: A− | Q18: =_xlfn.XLOOKUP(R18,Sports_details!B:B,Sports_details!A:A) -> INDOOR | R18: Handball | S18: 80.76 | T18: 106
A19: 18 | B19: =_xlfn.CONCAT(C19," ",D19," ",E19," ",F19) -> Hr. Richard Tlustek | C19: Hr. | D19: Richard | F19: Tlustek | G19: 1959 | H19: =DATE(G19,1,1) -> 21551 | I19: =2026-G19 -> 67 | J19: Virgo | K19: Male | L19: DE | M19: =_xlfn.XLOOKUP(L19,Location_details!$A$2:$M$2,Location_details!$A$3:$M$3) -> GERMANY | N19: =_xlfn.XLOOKUP(L19,Location_details!$A$2:$M$2,Location_details!$A$1:$M$1) -> German | O19: =LOWER(F19&"."&D19&"xyz.com") -> tlustek.richardxyz.com | P19: A− | Q19: =_xlfn.XLOOKUP(R19,Sports_details!B:B,Sports_details!A:A) -> OUTDOOR | R19: Cycling Mountain Bike | S19: 88.79 | T19: 71
A20: 19 | B20: =_xlfn.CONCAT(C20," ",D20," ",E20," ",F20) -> Dr. Earnestine Raynor | C20: Dr. | D20: Earnestine | F20: Raynor | G20: 1977 | H20: =DATE(G20,1,1) -> 28126 | I20: =2026-G20 -> 49 | J20: Taurus | K20: Female | L20: OZ | M20: =_xlfn.XLOOKUP(L20,Location_details!$A$2:$M$2,Location_details!$A$3:$M$3) -> AUSTRALIA | N20: =_xlfn.XLOOKUP(L20,Location_details!$A$2:$M$2,Location_details!$A$1:$M$1) -> English | O20: =LOWER(F20&"."&D20&"@xyz.org") -> raynor.earnestine@xyz.org | P20: A+ | Q20: =_xlfn.XLOOKUP(R20,Sports_details!B:B,Sports_details!A:A) -> INDOOR | R20: Short Track Speed Skating | S20: 63.53 | T20: 70
A21: 20 | B21: =_xlfn.CONCAT(C21," ",D21," ",E21," ",F21) -> Mr. Jason Gaylord | C21: Mr. | D21: Jason | F21: Gaylord | G21: 1976 | H21: =DATE(G21,1,1) -> 27760 | I21: =2026-G21 -> 50 | J21: Capricorn | K21: Male | L21: OZ | M21: =_xlfn.XLOOKUP(L21,Location_details!$A$2:$M$2,Location_details!$A$3:$M$3) -> AUSTRALIA | N21: =_xlfn.XLOOKUP(L21,Location_details!$A$2:$M$2,Location_details!$A$1:$M$1) -> English | O21: =LOWER(F21&"."&D21&"@xyz.org") -> gaylord.jason@xyz.org | P21: O− | Q21: =_xlfn.XLOOKUP(R21,Sports_details!B:B,Sports_details!A:A) -> INDOOR | R21: Basketball | S21: 46.35 | T21: 55
A22: 21 | B22: =_xlfn.CONCAT(C22," ",D22," ",E22," ",F22) -> Mr. Kendrick Sauer | C22: Mr. | D22: Kendrick | F22: Sauer | G22: 1996 | H22: =DATE(G22,1,1) -> 35065 | I22: =2026-G22 -> 30 | J22: Cancer | K22: Male | L22: OZ | M22: =_xlfn.XLOOKUP(L22,Location_details!$A$2:$M$2,Location_details!$A$3:$M$3) -> AUSTRALIA | N22: =_xlfn.XLOOKUP(L22,Location_details!$A$2:$M$2,Location_details!$A$1:$M$1) -> English | O22: =LOWER(F22&"."&D22&"@xyz.org") -> sauer.kendrick@xyz.org | P22: B− | Q22: =_xlfn.XLOOKUP(R22,Sports_details!B:B,Sports_details!A:A) -> OUTDOOR | R22: Triathlon | S22: 106.8 | T22: 101
A23: 22 | B23: =_xlfn.CONCAT(C23," ",D23," ",E23," ",F23) -> Dr. Annabell Olson | C23: Dr. | D23: Annabell | F23: Olson | G23: 1964 | H23: =DATE(G23,1,1) -> 23377 | I23: =2026-G23 -> 62 | J23: Aries | K23: Female | L23: OZ | M23: =_xlfn.XLOOKUP(L23,Location_details!$A$2:$M$2,Location_details!$A$3:$M$3) -> AUSTRALIA | N23: =_xlfn.XLOOKUP(L23,Location_details!$A$2:$M$2,Location_details!$A$1:$M$1) -> English | O23: =LOWER(F23&"."&D23&"@xyz.org") -> olson.annabell@xyz.org | P23: A+ | Q23: =_xlfn.XLOOKUP(R23,Sports_details!B:B,Sports_details!A:A) -> OUTDOOR | R23: Equestrian / Dressage | S23: 96.47 | T23: 84
A24: 23 | B24: =_xlfn.CONCAT(C24," ",D24," ",E24," ",F24) -> Dr. Jena Upton | C24: Dr. | D24: Jena | F24: Upton | G24: 1955 | H24: =DATE(G24,1,1) -> 20090 | I24: =2026-G24 -> 71 | J24: Sagittarius | K24: Female | L24: OZ | M24: =_xlfn.XLOOKUP(L24,Location_details!$A$2:$M$2,Location_details!$A$3:$M$3) -> AUSTRALIA | N24: =_xlfn.XLOOKUP(L24,Location_details!$A$2:$M$2,Location_details!$A$1:$M$1) -> English | O24: =LOWER(F24&"."&D24&"@xyz.org") -> upton.jena@xyz.org | P24: O+ | Q24: =_xlfn.XLOOKUP(R24,Sports_details!B:B,Sports_details!A:A) -> OUTDOOR | R24: Beach Volleyball | S24: 16.53 | T24: 67
A25: 24 | B25: =_xlfn.CONCAT(C25," ",D25," ",E25," ",F25) -> Dr. Shanny Bins | C25: Dr. | D25: Shanny | F25: Bins | G25: 1999 | H25: =DATE(G25,1,1) -> 36161 | I25: =2026-G25 -> 27 | J25: Virgo | K25: Female | L25: OZ | M25: =_xlfn.XLOOKUP(L25,Location_details!$A$2:$M$2,Location_details!$A$3:$M$3) -> AUSTRALIA | N25: =_xlfn.XLOOKUP(L25,Location_details!$A$2:$M$2,Location_details!$A$1:$M$1) -> English | O25: =LOWER(F25&"."&D25&"@xyz.org") -> bins.shanny@xyz.org | P25: B− | Q25: =_xlfn.XLOOKUP(R25,Sports_details!B:B,Sports_details!A:A) -> OUTDOOR | R25: Canoe Slalom | S25: 21.89 | T25: 59
A26: 25 | B26: =_xlfn.CONCAT(C26," ",D26," ",E26," ",F26) -> Dr. Tia Abshire | C26: Dr. | D26: Tia | F26: Abshire | G26: 1966 | H26: =DATE(G26,1,1) -> 24108 | I26: =2026-G26 -> 60 | J26: Cancer | K26: Female | L26: OZ | M26: =_xlfn.XLOOKUP(L26,Location_details!$A$2:$M$2,Location_details!$A$3:$M$3) -> AUSTRALIA | N26: =_xlfn.XLOOKUP(L26,Location_details!$A$2:$M$2,Location_details!$A$1:$M$1) -> English | O26: =LOWER(F26&"."&D26&"@xyz.org") -> abshire.tia@xyz.org | P26: A+ | Q26: =_xlfn.XLOOKUP(R26,Sports_details!B:B,Sports_details!A:A) -> OUTDOOR | R26: Cycling Road | S26: 62.04 | T26: 78
A27: 26 | B27: =_xlfn.CONCAT(C27," ",D27," ",E27," ",F27) -> Ms. Isabel Runolfsdottir | C27: Ms. | D27: Isabel | F27: Runolfsdottir | G27: 1978 | H27: =DATE(G27,1,1) -> 28491 | I27: =2026-G27 -> 48 | J27: Aries | K27: Female | L27: OZ | M27: =_xlfn.XLOOKUP(L27,Location_details!$A$2:$M$2,Location_details!$A$3:$M$3) -> AUSTRALIA | N27: =_xlfn.XLOOKUP(L27,Location_details!$A$2:$M$2,Location_details!$A$1:$M$1) -> English | O27: =LOWER(F27&"."&D27&"@xyz.org") -> runolfsdottir.isabel@xyz.org | P27: B+ | Q27: =_xlfn.XLOOKUP(R27,Sports_details!B:B,Sports_details!A:A) -> INDOOR | R27: Cycling Track | S27: 89.74 | T27: 86
A28: 27 | B28: =_xlfn.CONCAT(C28," ",D28," ",E28," ",F28) -> Hr. Barney Wesack | C28: Hr. | D28: Barney | F28: Wesack | G28: 1970 | H28: =DATE(G28,1,1) -> 25569 | I28: =2026-G28 -> 56 | J28: Cancer | K28: Male | L28: AU | M28: =_xlfn.XLOOKUP(L28,Location_details!$A$2:$M$2,Location_details!$A$3:$M$3) -> AUSTRIA | N28: =_xlfn.XLOOKUP(L28,Location_details!$A$2:$M$2,Location_details!$A$1:$M$1) -> German | O28: =LOWER(F28&"."&D28&"xyz.com") -> wesack.barneyxyz.com | P28: B+ | Q28: =_xlfn.XLOOKUP(R28,Sports_details!B:B,Sports_details!A:A) -> INDOOR | R28: Volleyball | S28: 41.04 | T28: 93
A29: 28 | B29: =_xlfn.CONCAT(C29," ",D29," ",E29," ",F29) -> Hr. Baruch Kade | C29: Hr. | D29: Baruch | F29: Kade | G29: 1982 | H29: =DATE(G29,1,1) -> 29952 | I29: =2026-G29 -> 44 | J29: Pisces | K29: Male | L29: AU | M29: =_xlfn.XLOOKUP(L29,Location_details!$A$2:$M$2,Location_details!$A$3:$M$3) -> AUSTRIA | N29: =_xlfn.XLOOKUP(L29,Location_details!$A$2:$M$2,Location_details!$A$1:$M$1) -> German | O29: =LOWER(F29&"."&D29&"xyz.com") -> kade.baruchxyz.com | P29: O− | Q29: =_xlfn.XLOOKUP(R29,Sports_details!B:B,Sports_details!A:A) -> OUTDOOR | R29: Rugby | S29: 28.46 | T29: 96
A30: 29 | B30: =_xlfn.CONCAT(C30," ",D30," ",E30," ",F30) -> Prof. Liesbeth Rosemann | C30: Prof. | D30: Liesbeth | F30: Rosemann | G30: 1994 | H30: =DATE(G30,1,1) -> 34335 | I30: =2026-G30 -> 32 | J30: Aquarius | K30: Female | L30: AU | M30: =_xlfn.XLOOKUP(L30,Location_details!$A$2:$M$2,Location_details!$A$3:$M$3) -> AUSTRIA | N30: =_xlfn.XLOOKUP(L30,Location_details!$A$2:$M$2,Location_details!$A$1:$M$1) -> German | O30: =LOWER(F30&"."&D30&"xyz.com") -> rosemann.liesbethxyz.com | P30: O+ | Q30: =_xlfn.XLOOKUP(R30,Sports_details!B:B,Sports_details!A:A) -> OUTDOOR | R30: Cycling Road | S30: 55.01 | T30: 52
A31: 30 | B31: =_xlfn.CONCAT(C31," ",D31," ",E31," ",F31) -> Mme. Valentine Moreau | C31: Mme. | D31: Valentine | F31: Moreau | G31: 1979 | H31: =DATE(G31,1,1) -> 28856 | I31: =2026-G31 -> 47 | J31: Libra | K31: Female | L31: FR | M31: =_xlfn.XLOOKUP(L31,Location_details!$A$2:$M$2,Location_details!$A$3:$M$3) -> FRANCE | N31: =_xlfn.XLOOKUP(L31,Location_details!$A$2:$M$2,Location_details!$A$1:$M$1) -> French | O31: =LOWER(F31&"."&D31&"xyz.com") -> moreau.valentinexyz.com | P31: B+ | Q31: =_xlfn.XLOOKUP(R31,Sports_details!B:B,Sports_details!A:A) -> OUTDOOR | R31: Golf | S31: 69.04 | T31: 75
A32: 31 | B32: =_xlfn.CONCAT(C32," ",D32," ",E32," ",F32) -> Mme. Paulette Durand | C32: Mme. | D32: Paulette | F32: Durand | G32: 1989 | H32: =DATE(G32,1,1) -> 32509 | I32: =2026-G32 -> 37 | J32: Capricorn | K32: Female | L32: FR | M32: =_xlfn.XLOOKUP(L32,Location_details!$A$2:$M$2,Location_details!$A$3:$M$3) -> FRANCE | N32: =_xlfn.XLOOKUP(L32,Location_details!$A$2:$M$2,Location_details!$A$1:$M$1) -> French | O32: =LOWER(F32&"."&D32&"xyz.com") -> durand.paulettexyz.com | P32: O− | Q32: =_xlfn.XLOOKUP(R32,Sports_details!B:B,Sports_details!A:A) -> INDOOR | R32: Volleyball | S32: 86.26 | T32: 82
A33: 32 | B33: =_xlfn.CONCAT(C33," ",D33," ",E33," ",F33) -> Mme. Laure-Alix Chevalier | C33: Mme. | D33: Laure-Alix | F33: Chevalier | G33: 1970 | H33: =DATE(G33,1,1) -> 25569 | I33: =2026-G33 -> 56 | J33: Capricorn | K33: Female | L33: FR | M33: =_xlfn.XLOOKUP(L33,Location_details!$A$2:$M$2,Location_details!$A$3:$M$3) -> FRANCE | N33: =_xlfn.XLOOKUP(L33,Location_details!$A$2:$M$2,Location_details!$A$1:$M$1) -> French | O33: =LOWER(F33&"."&D33&"xyz.com") -> chevalier.laure-alixxyz.com | P33: O+ | Q33: =_xlfn.XLOOKUP(R33,Sports_details!B:B,Sports_details!A:A) -> OUTDOOR | R33: Beach Volleyball | S33: 19.23 | T33: 78
A34: 33 | B34: =_xlfn.CONCAT(C34," ",D34," ",E34," ",F34) -> M. Claude Toussaint | C34: M. | D34: Claude | F34: Toussaint | G34: 1980 | H34: =DATE(G34,1,1) -> 29221 | I34: =2026-G34 -> 46 | J34: Scorpio | K34: Male | L34: FR | M34: =_xlfn.XLOOKUP(L34,Location_details!$A$2:$M$2,Location_details!$A$3:$M$3) -> FRANCE | N34: =_xlfn.XLOOKUP(L34,Location_details!$A$2:$M$2,Location_details!$A$1:$M$1) -> French | O34: =LOWER(F34&"."&D34&"xyz.com") -> toussaint.claudexyz.com | P34: O+ | Q34: =_xlfn.XLOOKUP(R34,Sports_details!B:B,Sports_details!A:A) -> INDOOR | R34: Diving | S34: 95.12 | T34: 57
A35: 34 | B35: =_xlfn.CONCAT(C35," ",D35," ",E35," ",F35) -> M. Victor Lenoir | C35: M. | D35: Victor | F35: Lenoir | G35: 1981 | H35: =DATE(G35,1,1) -> 29587 | I35: =2026-G35 -> 45 | J35: Libra | K35: Male | L35: FR | M35: =_xlfn.XLOOKUP(L35,Location_details!$A$2:$M$2,Location_details!$A$3:$M$3) -> FRANCE | N35: =_xlfn.XLOOKUP(L35,Location_details!$A$2:$M$2,Location_details!$A$1:$M$1) -> French | O35: =LOWER(F35&"."&D35&"xyz.com") -> lenoir.victorxyz.com | P35: B+ | Q35: =_xlfn.XLOOKUP(R35,Sports_details!B:B,Sports_details!A:A) -> OUTDOOR | R35: Triathlon | S35: 62.76 | T35: 56
A36: 35 | B36: =_xlfn.CONCAT(C36," ",D36," ",E36," ",F36) -> M. Arthur Lenoir | C36: M. | D36: Arthur | F36: Lenoir | G36: 1955 | H36: =DATE(G36,1,1) -> 20090 | I36: =2026-G36 -> 71 | J36: Leo | K36: Male | L36: FR | M36: =_xlfn.XLOOKUP(L36,Location_details!$A$2:$M$2,Location_details!$A$3:$M$3) -> FRANCE | N36: =_xlfn.XLOOKUP(L36,Location_details!$A$2:$M$2,Location_details!$A$1:$M$1) -> French | O36: =LOWER(F36&"."&D36&"xyz.com") -> lenoir.arthurxyz.com | P36: O+ | Q36: =_xlfn.XLOOKUP(R36,Sports_details!B:B,Sports_details!A:A) -> OUTDOOR | R36: Hockey | S36: 108.4 | T36: 89
A37: 36 | B37: =_xlfn.CONCAT(C37," ",D37," ",E37," ",F37) -> M. Benjamin Lebrun-Brun | C37: M. | D37: Benjamin | F37: Lebrun-Brun | G37: 1975 | H37: =DATE(G37,1,1) -> 27395 | I37: =2026-G37 -> 51 | J37: Aquarius | K37: Male | L37: FR | M37: =_xlfn.XLOOKUP(L37,Location_details!$A$2:$M$2,Location_details!$A$3:$M$3) -> FRANCE | N37: =_xlfn.XLOOKUP(L37,Location_details!$A$2:$M$2,Location_details!$A$1:$M$1) -> French | O37: =LOWER(F37&"."&D37&"xyz.com") -> lebrun-brun.benjaminxyz.com | P37: O− | Q37: =_xlfn.XLOOKUP(R37,Sports_details!B:B,Sports_details!A:A) -> OUTDOOR | R37: Triathlon | S37: 66.27 | T37: 78
A38: 37 | B38: =_xlfn.CONCAT(C38," ",D38," ",E38," ",F38) -> M. Antoine Maillard | C38: M. | D38: Antoine | F38: Maillard | G38: 1986 | H38: =DATE(G38,1,1) -> 31413 | I38: =2026-G38 -> 40 | J38: Cancer | K38: Male | L38: FR | M38: =_xlfn.XLOOKUP(L38,Location_details!$A$2:$M$2,Location_details!$A$3:$M$3) -> FRANCE | N38: =_xlfn.XLOOKUP(L38,Location_details!$A$2:$M$2,Location_details!$A$1:$M$1) -> French | O38: =LOWER(F38&"."&D38&"xyz.com") -> maillard.antoinexyz.com | P38: B− | Q38: =_xlfn.XLOOKUP(R38,Sports_details!B:B,Sports_details!A:A) -> OUTDOOR | R38: Sailing | S38: 33.97 | T38: 96
A39: 38 | B39: =_xlfn.CONCAT(C39," ",D39," ",E39," ",F39) -> M. Bernard Hoarau-Guyon | C39: M. | D39: Bernard | F39: Hoarau-Guyon | G39: 1983 | H39: =DATE(G39,1,1) -> 30317 | I39: =2026-G39 -> 43 | J39: Capricorn | K39: Male | L39: FR | M39: =_xlfn.XLOOKUP(L39,Location_details!$A$2:$M$2,Location_details!$A$3:$M$3) -> FRANCE | N39: =_xlfn.XLOOKUP(L39,Location_details!$A$2:$M$2,Location_details!$A$1:$M$1) -> French | O39: =LOWER(F39&"."&D39&"xyz.com") -> hoarau-guyon.bernardxyz.com | P39: O− | Q39: =_xlfn.XLOOKUP(R39,Sports_details!B:B,Sports_details!A:A) -> INDOOR | R39: Cycling Track | S39: 71.35 | T39: 60
A40: 39 | B40: =_xlfn.CONCAT(C40," ",D40," ",E40," ",F40) -> Sr. Hidalgo Cantu Tercero | C40: Sr. | D40: Hidalgo | E40: Cantu | F40: Tercero | G40: 1984 | H40: =DATE(G40,1,1) -> 30682 | I40: =2026-G40 -> 42 | J40: Sagittarius | K40: Male | L40: AG | M40: =_xlfn.XLOOKUP(L40,Location_details!$A$2:$M$2,Location_details!$A$3:$M$3) -> ARGENTINA | N40: =_xlfn.XLOOKUP(L40,Location_details!$A$2:$M$2,Location_details!$A$1:$M$1) -> Spanish | O40: =LOWER(F40&"."&D40&"xyz.com") -> tercero.hidalgoxyz.com | P40: B− | Q40: =_xlfn.XLOOKUP(R40,Sports_details!B:B,Sports_details!A:A) -> OUTDOOR | R40: Canoe Slalom | S40: 116.4 | T40: 78
...

Sheet Sportsperson country and gender
A3: Count of MEMBER ID | B3: Column Labels
A4: Row Labels | B4: Female | C4: Male | D4: Grand Total
A5: ARGENTINA | B5: 1 | C5: 2 | D5: 3
A6: AUSTRALIA | B6: 6 | C6: 2 | D6: 8
A7: AUSTRIA | B7: 1 | C7: 2 | D7: 3
A8: BRAZIL | C8: 2 | D8: 2
A9: FRANCE | B9: 3 | C9: 6 | D9: 9
A10: GERMANY | B10: 1 | C10: 4 | D10: 5
A11: NETHERLANDS | B11: 2 | C11: 1 | D11: 3
A12: SPAIN | B12: 3 | D12: 3
A13: SWEDEN | B13: 1 | C13: 1 | D13: 2
A14: UK | B14: 3 | C14: 2 | D14: 5
A15: USA | B15: 4 | C15: 3 | D15: 7
A16: Grand Total | B16: 25 | C16: 25 | D16: 50

Sheet Salary country and Gender wise
A3: Sum of SALARY | B3: Column Labels
A4: Row Labels | B4: Female | C4: Male | D4: Grand Total
A5: ARGENTINA | B5: 79.87 | C5: 230.5 | D5: 310.37
A6: AUSTRALIA | B6: 350.2 | C6: 153.15 | D6: 503.35
A7: AUSTRIA | B7: 55.01 | C7: 69.5 | D7: 124.51
A8: BRAZIL | C8: 85.25 | D8: 85.25
A9: FRANCE | B9: 174.53 | C9: 437.87 | D9: 612.4
A10: GERMANY | B10: 10.24 | C10: 323.17 | D10: 333.41
A11: NETHERLANDS | B11: 130.42 | C11: 44.87 | D11: 175.29
A12: SPAIN | B12: 210.88 | D12: 210.88
A13: SWEDEN | B13: 38.97 | C13: 35.39 | D13: 74.36
A14: UK | B14: 234.06 | C14: 132.37 | D14: 366.43
A15: USA | B15: 344.47 | C15: 217.95 | D15: 562.42
A16: Grand Total | B16: 1628.65 | C16: 1730.02 | D16: 3358.67

Sheet age vs salary
A3: Row Labels | B3: Sum of SALARY
A4: 27 | B4: 87.36 | E4: 27 | F4: 87.36
A5: 29 | B5: 119.7 | E5: 29 | F5: 119.7
A6: 30 | B6: 106.8 | E6: 30 | F6: 106.8
A7: 32 | B7: 55.01 | E7: 32 | F7: 55.01
A8: 33 | B8: 20.53 | E8: 33 | F8: 20.53
A9: 34 | B9: 138.6 | E9: 34 | F9: 138.6
A10: 36 | B10: 102 | E10: 36 | F10: 102
A11: 37 | B11: 86.26 | E11: 37 | F11: 86.26
A12: 38 | B12: 114.1 | E12: 38 | F12: 114.1
A13: 39 | B13: 35.39 | E13: 39 | F13: 35.39
A14: 40 | B14: 133.58 | E14: 40 | F14: 133.58
A15: 42 | B15: 116.4 | E15: 42 | F15: 116.4
... A38: 71 | B38: 124.93 | E38: 71 | F38: 124.93
A39: Formula1
A40: Formula2
A41: Formula3
A42: Formula4
A43: Formula5
A44: Grand Total | B44: 3358.67

Sheet Average Weight sports wise
A3: Average of wt. | B3: Column Labels
A4: Row Labels | B4: Alpine Skiing | C4: Archery | D4: Athletics | E4: Basketball | F4: Beach Volleyball | G4: Biathlon | H4: Boxing | I4: Canoe Slalom | J4: Canoe Sprint | K4: Curling | L4: Cycling BMX | M4: Cycling Mountain Bike | N4: Cycling Road | O4: Cycling Track | P4: Diving | Q4: Equestrian / Dressage | R4: Fencing | S4: Football | T4: Freestyle Skiing | U4: Golf | V4: Gymnastics Artistic | W4: Handball | X4: Hockey | Y4: Judo | Z4: Rugby | AA4: Sailing | AB4: Shooting | AC4: Short Track Speed Skating | AD4: Swimming | AE4: Triathlon | AF4: Volleyball | AG4: Water Polo | AH4: Grand Total
A5: ARGENTINA | D5: 52 | F5: 98 | I5: 78 | AH5: 76
A6: AUSTRALIA | E6: 55 | F6: 67 | I6: 59 | N6: 78 | O6: 86 | Q6: 84 | AC6: 70 | AE6: 101 | AH6: 75
A7: AUSTRIA | N7: 52 | Z7: 96 | AF7: 93 | AH7: 80.333333
A8: BRAZIL | S8: 53 | AD8: 93 | AH8: 73
A9: FRANCE | F9: 78 | O9: 60 | P9: 57 | U9: 75 | X9: 89 | AA9: 96 | AE9: 67 | AF9: 82 | AH9: 74.555556
A10: GERMANY | B10: 49 | J10: 68 | L10: 105 | M10: 71 | W10: 106 | AH10: 79.8
A11: NETHERLANDS | F11: 80.5 | Y11: 64 | AH11: 75
A12: SPAIN | D12: 59 | I12: 102 | V12: 56 | AH12: 72.333333
A13: SWEDEN | G13: 46 | S13: 50 | AH13: 48
A14: UK | C14: 101 | N14: 63 | T14: 104 | Z14: 71 | AB14: 65 | AH14: 80.8
A15: USA | B15: 49 | H15: 84 | K15: 106 | N15: 61 | O15: 94 | R15: 83 | AG15: 85 | AH15: 80.285714
A16: Grand Total | B16: 49 | C16: 101 | D16: 55.5 | E16: 55 | F16: 80.8 | G16: 46 | H16: 84 | I16: 79.666667 | J16: 68 | K16: 106 | L16: 105 | M16: 71 | N16: 63.5 | O16: 80 | P16: 57 | Q16: 84 | R16: 83 | S16: 51.5 | T16: 104 | U16: 75 | V16: 56 | W16: 106 | X16: 89 | Y16: 64 | Z16: 83.5 | AA16: 96 | AB16: 65 | AC16: 70 | AD16: 93 | AE16: 78.333333 | AF16: 87.5 | AG16: 85 | AH16: 75.78

Sheet DASHBOARD
